Workbook

Sheet Documentation
A1: College Decision Analytics Dashboard
A2: By Jackson Frisby
A3: Purpose: The purpose of this project is to provide a
A4: dashboard for high school students to explore
A5: colleges that are within their budget and preferred
A6: location. This file also gives the option to look into
A7: the top five majors in their top five ranked schools.

Sheet Info

Sheet School 1

Sheet School 2

Sheet School 3

Sheet School 4
J3: ='College Logo'!P1 -> FALSE

Sheet School 5
J3: ='College Logo'!P1 -> FALSE

Sheet TopMajorSummary

Sheet SchoolRankings
A1: UNITID | B1: INSTNM | C1: CITY | D1: STABBR | E1: INSTURL | F1: ADM_RATE | G1: SAT_AVG | H1: TUITIONFEE_IN | I1: TUITIONFEE_OUT | J1: MD_EARN_WNE_5YR | K1: MD_EARN_WNE_P7 | L1: MD_EARN_WNE_P9 | M1: MD_EARN_WNE_P11 | N1: In State Rank | O1: Out Of State Rank | P1: In-State Rank # | Q1: Out-of-State Rank # | R1: LOGO_URL | S1: DOMAIN
A2: 100654 | B2: Alabama A & M University | C2: Normal | D2: AL | E2: www.aamu.edu/ | F2: 0.6622 | G2: 947 | H2: 10024 | I2: 18634 | J2: 52246 | K2: 28974 | L2: 35438 | M2: 39059 | N2: =IFERROR( 0.25*(_xlfn.MAXIFS($H:$H,$D:$D,$D2)-H2)/(_xlfn.MAXIFS($H:$H,$D:$D,$D2)-_xlfn.MINIFS($H:$H,$D:$D,$D2)) + 0.2*(_xlfn.MAXIFS($F:$F,$D:$D,$D2)-F2)/(_xlfn.MAXIFS($F:$F,$D:$D,$D2)-_xlfn.MINIFS($F:$F,$D:$D,$D2)) + 0.3*(G2-_xlfn.MINIFS($G:$G,$D:$D,$D2))/(_xlfn.MAXIFS($G:$G,$D:$D,$D2)-_xlfn.MINIFS($G:$G,$D:$D,$D2)) + 0.125*(J2-_xlfn.MINIFS($J:$J,$D:$D,$D2))/(_xlfn.MAXIFS($J:$J,$D:$D,$D2)-_xlfn.MINIFS($J:$J,$D:$D,$D2)) + 0.125*(K2-_xlfn.MINIFS($K:$K,$D:$D,$D2))/(_xlfn.MAXIFS($K:$K,$D:$D,$D2)-_xlfn.MINIFS($K:$K,$D:$D,$D2)), "") -> 0.39123999 | O2: =0.3*((MAX($I$2:$I$2303)-I2)/(MAX($I$2:$I$2303)-MIN($I$2:$I$2303))) +0.3*((J2-MIN($J$2:$J$2303))/(MAX($J$2:$J$2303)-MIN($J$2:$J$2303))) +0.25*((G2-MIN($G$2:$G$2303))/(MAX($G$2:$G$2303)-MIN($G$2:$G$2303))) +0.15*((MAX($F$2:$F$2303)-F2)/(MAX($F$2:$F$2303)-MIN($F$2:$F$2303))) -> 0.39962514 | P2: =1 + COUNTIFS($D$2:$D$2303, D2, $N$2:$N$2303, ">" & N2) -> 27 | Q2: =1 + COUNTIFS($D$2:$D$2303, D2, $O$2:$O$2303, ">" & O2) -> 18 | R2: =IF(S2="","", "https://img.logo.dev/" & S2 & "?token=pk_Zxmaeq2VQBuxgzPsrb7eBg&size=256" ) -> https://img.logo.dev/www.aamu.edu?token=pk_Zxmaeq2VQBuxgzPsrb7eBg&size=256 | S2: =_xlfn.LET( _xlpm.url, E2, _xlpm.noProto, IFERROR(_xlfn.TEXTAFTER(_xlpm.url,"//"), _xlpm.url), _xlpm.noSlash, LEFT(_xlpm.noProto, FIND("/", _xlpm.noProto&"/")-1), _xlpm.noQuery, LEFT(_xlpm.noSlash, FIND("?", _xlpm.noSlash&"?")-1), LOWER(_xlpm.noQuery) ) -> www.aamu.edu
A3: 100663 | B3: University of Alabama at Birmingham | C3: Birmingham | D3: AL | E3: https://www.uab.edu/ | F3: 0.8842 | G3: 1251 | H3: 8832 | I3: 21864 | J3: 60738 | K3: 42911 | L3: 45795 | M3: 50907 | N3: =IFERROR( 0.25*(_xlfn.MAXIFS($H:$H,$D:$D,$D3)-H3)/(_xlfn.MAXIFS($H:$H,$D:$D,$D3)-_xlfn.MINIFS($H:$H,$D:$D,$D3)) + 0.2*(_xlfn.MAXIFS($F:$F,$D:$D,$D3)-F3)/(_xlfn.MAXIFS($F:$F,$D:$D,$D3)-_xlfn.MINIFS($F:$F,$D:$D,$D3)) + 0.3*(G3-_xlfn.MINIFS($G:$G,$D:$D,$D3))/(_xlfn.MAXIFS($G:$G,$D:$D,$D3)-_xlfn.MINIFS($G:$G,$D:$D,$D3)) + 0.125*(J3-_xlfn.MINIFS($J:$J,$D:$D,$D3))/(_xlfn.MAXIFS($J:$J,$D:$D,$D3)-_xlfn.MINIFS($J:$J,$D:$D,$D3)) + 0.125*(K3-_xlfn.MINIFS($K:$K,$D:$D,$D3))/(_xlfn.MAXIFS($K:$K,$D:$D,$D3)-_xlfn.MINIFS($K:$K,$D:$D,$D3)), "") -> 0.66220919 | O3: 0.47223813 | P3: =1 + COUNTIFS($D$2:$D$2303, D3, $N$2:$N$2303, ">" & N3) -> 4 | Q3: 7 | R3: https://img.logo.dev/www.uab.edu?token=pk_Zxmaeq2VQBuxgzPsrb7eBg&size=256 | S3: www.uab.edu
A4: 100690 | B4: Amridge University | C4: Montgomery | D4: AL | E4: https://www.amridgeuniversity.edu/ | F4: 0.99 | G4: 1208 | H4: 6950 | I4: 6950 | J4: 49649 | K4: 27988 | L4: 34571 | M4: 37730 | N4: =IFERROR( 0.25*(_xlfn.MAXIFS($H:$H,$D:$D,$D4)-H4)/(_xlfn.MAXIFS($H:$H,$D:$D,$D4)-_xlfn.MINIFS($H:$H,$D:$D,$D4)) + 0.2*(_xlfn.MAXIFS($F:$F,$D:$D,$D4)-F4)/(_xlfn.MAXIFS($F:$F,$D:$D,$D4)-_xlfn.MINIFS($F:$F,$D:$D,$D4)) + 0.3*(G4-_xlfn.MINIFS($G:$G,$D:$D,$D4))/(_xlfn.MAXIFS($G:$G,$D:$D,$D4)-_xlfn.MINIFS($G:$G,$D:$D,$D4)) + 0.125*(J4-_xlfn.MINIFS($J:$J,$D:$D,$D4))/(_xlfn.MAXIFS($J:$J,$D:$D,$D4)-_xlfn.MINIFS($J:$J,$D:$D,$D4)) + 0.125*(K4-_xlfn.MINIFS($K:$K,$D:$D,$D4))/(_xlfn.MAXIFS($K:$K,$D:$D,$D4)-_xlfn.MINIFS($K:$K,$D:$D,$D4)), "") -> 0.51627378 | O4: 0.42935486 | P4: =1 + COUNTIFS($D$2:$D$2303, D4, $N$2:$N$2303, ">" & N4) -> 10 | Q4: 17 | R4: https://img.logo.dev/www.amridgeuniversity.edu?token=pk_Zxmaeq2VQBuxgzPsrb7eBg&size=256 | S4: www.amridgeuniversity.edu
A5: 100706 | B5: University of Alabama in Huntsville | C5: Huntsville | D5: AL | E5: www.uah.edu/ | F5: 0.7425 | G5: 1321 | H5: 11770 | I5: 24662 | J5: 78740 | K5: 52360 | L5: 53186 | M5: 56901 | N5: =IFERROR( 0.25*(_xlfn.MAXIFS($H:$H,$D:$D,$D5)-H5)/(_xlfn.MAXIFS($H:$H,$D:$D,$D5)-_xlfn.MINIFS($H:$H,$D:$D,$D5)) + 0.2*(_xlfn.MAXIFS($F:$F,$D:$D,$D5)-F5)/(_xlfn.MAXIFS($F:$F,$D:$D,$D5)-_xlfn.MINIFS($F:$F,$D:$D,$D5)) + 0.3*(G5-_xlfn.MINIFS($G:$G,$D:$D,$D5))/(_xlfn.MAXIFS($G:$G,$D:$D,$D5)-_xlfn.MINIFS($G:$G,$D:$D,$D5)) + 0.125*(J5-_xlfn.MINIFS($J:$J,$D:$D,$D5))/(_xlfn.MAXIFS($J:$J,$D:$D,$D5)-_xlfn.MINIFS($J:$J,$D:$D,$D5)) + 0.125*(K5-_xlfn.MINIFS($K:$K,$D:$D,$D5))/(_xlfn.MAXIFS($K:$K,$D:$D,$D5)-_xlfn.MINIFS($K:$K,$D:$D,$D5)), "") -> 0.82894392 | O5: 0.54351734 | P5: =1 + COUNTIFS($D$2:$D$2303, D5, $N$2:$N$2303, ">" & N5) -> 2 | Q5: 1 | R5: https://img.logo.dev/www.uah.edu?token=pk_Zxmaeq2VQBuxgzPsrb7eBg&size=256 | S5: www.uah.edu
A6: 100724 | B6: Alabama State University | C6: Montgomery | D6: AL | E6: www.alasu.edu/ | F6: 0.9564 | G6: 977 | H6: 11248 | I6: 19576 | J6: 43913 | K6: 26395 | L6: 30177 | M6: 34018 | N6: =IFERROR( 0.25*(_xlfn.MAXIFS($H:$H,$D:$D,$D6)-H6)/(_xlfn.MAXIFS($H:$H,$D:$D,$D6)-_xlfn.MINIFS($H:$H,$D:$D,$D6)) + 0.2*(_xlfn.MAXIFS($F:$F,$D:$D,$D6)-F6)/(_xlfn.MAXIFS($F:$F,$D:$D,$D6)-_xlfn.MINIFS($F:$F,$D:$D,$D6)) + 0.3*(G6-_xlfn.MINIFS($G:$G,$D:$D,$D6))/(_xlfn.MAXIFS($G:$G,$D:$D,$D6)-_xlfn.MINIFS($G:$G,$D:$D,$D6)) + 0.125*(J6-_xlfn.MINIFS($J:$J,$D:$D,$D6))/(_xlfn.MAXIFS($J:$J,$D:$D,$D6)-_xlfn.MINIFS($J:$J,$D:$D,$D6)) + 0.125*(K6-_xlfn.MINIFS($K:$K,$D:$D,$D6))/(_xlfn.MAXIFS($K:$K,$D:$D,$D6)-_xlfn.MINIFS($K:$K,$D:$D,$D6)), "") -> 0.28411681 | O6: 0.34218587 | P6: =1 + COUNTIFS($D$2:$D$2303, D6, $N$2:$N$2303, ">" & N6) -> 30 | Q6: 40 | R6: https://img.logo.dev/www.alasu.edu?token=pk_Zxmaeq2VQBuxgzPsrb7eBg&size=256 | S6: www.alasu.edu
A7: 100751 | B7: The University of Alabama | C7: Tuscaloosa | D7: AL | E7: www.ua.edu/ | F7: 0.7582 | G7: 1287 | H7: 11900 | I7: 33200 | J7: 62983 | K7: 48273 | L7: 51441 | M7: 56118 | N7: =IFERROR( 0.25*(_xlfn.MAXIFS($H:$H,$D:$D,$D7)-H7)/(_xlfn.MAXIFS($H:$H,$D:$D,$D7)-_xlfn.MINIFS($H:$H,$D:$D,$D7)) + 0.2*(_xlfn.MAXIFS($F:$F,$D:$D,$D7)-F7)/(_xlfn.MAXIFS($F:$F,$D:$D,$D7)-_xlfn.MINIFS($F:$F,$D:$D,$D7)) + 0.3*(G7-_xlfn.MINIFS($G:$G,$D:$D,$D7))/(_xlfn.MAXIFS($G:$G,$D:$D,$D7)-_xlfn.MINIFS($G:$G,$D:$D,$D7)) + 0.125*(J7-_xlfn.MINIFS($J:$J,$D:$D,$D7))/(_xlfn.MAXIFS($J:$J,$D:$D,$D7)-_xlfn.MINIFS($J:$J,$D:$D,$D7)) + 0.125*(K7-_xlfn.MINIFS($K:$K,$D:$D,$D7))/(_xlfn.MAXIFS($K:$K,$D:$D,$D7)-_xlfn.MINIFS($K:$K,$D:$D,$D7)), "") -> 0.73340772 | O7: 0.45870734 | P7: =1 + COUNTIFS($D$2:$D$2303, D7, $N$2:$N$2303, ">" & N7) -> 3 | Q7: 9 | R7: https://img.logo.dev/www.ua.edu?token=pk_Zxmaeq2VQBuxgzPsrb7eBg&size=256 | S7: www.ua.edu
A8: 100812 | B8: Athens State University | C8: Athens | D8: AL | E8: https://www.athens.edu/ | F8: 0.593 | G8: 1163 | H8: 27961 | I8: 29539 | J8: 50817 | K8: 42451 | L8: 44817 | M8: 45311 | N8: =IFERROR( 0.25*(_xlfn.MAXIFS($H:$H,$D:$D,$D8)-H8)/(_xlfn.MAXIFS($H:$H,$D:$D,$D8)-_xlfn.MINIFS($H:$H,$D:$D,$D8)) + 0.2*(_xlfn.MAXIFS($F:$F,$D:$D,$D8)-F8)/(_xlfn.MAXIFS($F:$F,$D:$D,$D8)-_xlfn.MINIFS($F:$F,$D:$D,$D8)) + 0.3*(G8-_xlfn.MINIFS($G:$G,$D:$D,$D8))/(_xlfn.MAXIFS($G:$G,$D:$D,$D8)-_xlfn.MINIFS($G:$G,$D:$D,$D8)) + 0.125*(J8-_xlfn.MINIFS($J:$J,$D:$D,$D8))/(_xlfn.MAXIFS($J:$J,$D:$D,$D8)-_xlfn.MINIFS($J:$J,$D:$D,$D8)) + 0.125*(K8-_xlfn.MINIFS($K:$K,$D:$D,$D8))/(_xlfn.MAXIFS($K:$K,$D:$D,$D8)-_xlfn.MINIFS($K:$K,$D:$D,$D8)), "") -> 0.49775012 | O8: 0.39279715 | P8: =1 + COUNTIFS($D$2:$D$2303, D8, $N$2:$N$2303, ">" & N8) -> 14 | Q8: 28 | R8: https://img.logo.dev/www.athens.edu?token=pk_Zxmaeq2VQBuxgzPsrb7eBg&size=256 | S8: www.athens.edu
A9: 100830 | B9: Auburn University at Montgomery | C9: Montgomery | D9: AL | E9: www.aum.edu/ | F9: 0.9263 | G9: 1090 | H9: 9436 | I9: 20092 | J9: 54405 | K9: 37969 | L9: 39396 | M9: 43743 | N9: =IFERROR( 0.25*(_xlfn.MAXIFS($H:$H,$D:$D,$D9)-H9)/(_xlfn.MAXIFS($H:$H,$D:$D,$D9)-_xlfn.MINIFS($H:$H,$D:$D,$D9)) + 0.2*(_xlfn.MAXIFS($F:$F,$D:$D,$D9)-F9)/(_xlfn.MAXIFS($F:$F,$D:$D,$D9)-_xlfn.MINIFS($F:$F,$D:$D,$D9)) + 0.3*(G9-_xlfn.MINIFS($G:$G,$D:$D,$D9))/(_xlfn.MAXIFS($G:$G,$D:$D,$D9)-_xlfn.MINIFS($G:$G,$D:$D,$D9)) + 0.125*(J9-_xlfn.MINIFS($J:$J,$D:$D,$D9))/(_xlfn.MAXIFS($J:$J,$D:$D,$D9)-_xlfn.MINIFS($J:$J,$D:$D,$D9)) + 0.125*(K9-_xlfn.MINIFS($K:$K,$D:$D,$D9))/(_xlfn.MAXIFS($K:$K,$D:$D,$D9)-_xlfn.MINIFS($K:$K,$D:$D,$D9)), "") -> 0.47684066 | O9: 0.405314 | P9: =1 + COUNTIFS($D$2:$D$2303, D9, $N$2:$N$2303, ">" & N9) -> 16 | Q9: 23 | R9: https://img.logo.dev/www.aum.edu?token=pk_Zxmaeq2VQBuxgzPsrb7eBg&size=256 | S9: www.aum.edu
A10: 100858 | B10: Auburn University | C10: Auburn | D10: AL | E10: www.auburn.edu/ | F10: 0.5047 | G10: 1318 | H10: 12536 | I10: 33944 | J10: 68172 | K10: 52489 | L10: 56937 | M10: 61042 | N10: =IFERROR( 0.25*(_xlfn.MAXIFS($H:$H,$D:$D,$D10)-H10)/(_xlfn.MAXIFS($H:$H,$D:$D,$D10)-_xlfn.MINIFS($H:$H,$D:$D,$D10)) + 0.2*(_xlfn.MAXIFS($F:$F,$D:$D,$D10)-F10)/(_xlfn.MAXIFS($F:$F,$D:$D,$D10)-_xlfn.MINIFS($F:$F,$D:$D,$D10)) + 0.3*(G10-_xlfn.MINIFS($G:$G,$D:$D,$D10))/(_xlfn.MAXIFS($G:$G,$D:$D,$D10)-_xlfn.MINIFS($G:$G,$D:$D,$D10)) + 0.125*(J10-_xlfn.MINIFS($J:$J,$D:$D,$D10))/(_xlfn.MAXIFS($J:$J,$D:$D,$D10)-_xlfn.MINIFS($J:$J,$D:$D,$D10)) + 0.125*(K10-_xlfn.MINIFS($K:$K,$D:$D,$D10))/(_xlfn.MAXIFS($K:$K,$D:$D,$D10)-_xlfn.MINIFS($K:$K,$D:$D,$D10)), "") -> 0.86080688 | O10: 0.5151107 | P10: =1 + COUNTIFS($D$2:$D$2303, D10, $N$2:$N$2303, ">" & N10) -> 1 | Q10: 2 | R10: https://img.logo.dev/www.auburn.edu?token=pk_Zxmaeq2VQBuxgzPsrb7eBg&size=256 | S10: www.auburn.edu
A11: 100937 | B11: Birmingham-Southern College | C11: Birmingham | D11: AL | E11: www.bsc.edu/ | F11: 0.5194 | G11: 1197 | H11: 22750 | I11: 22750 | J11: 56625 | K11: 45292 | L11: 50580 | M11: 55236 | N11: =IFERROR( 0.25*(_xlfn.MAXIFS($H:$H,$D:$D,$D11)-H11)/(_xlfn.MAXIFS($H:$H,$D:$D,$D11)-_xlfn.MINIFS($H:$H,$D:$D,$D11)) + 0.2*(_xlfn.MAXIFS($F:$F,$D:$D,$D11)-F11)/(_xlfn.MAXIFS($F:$F,$D:$D,$D11)-_xlfn.MINIFS($F:$F,$D:$D,$D11)) + 0.3*(G11-_xlfn.MINIFS($G:$G,$D:$D,$D11))/(_xlfn.MAXIFS($G:$G,$D:$D,$D11)-_xlfn.MINIFS($G:$G,$D:$D,$D11)) + 0.125*(J11-_xlfn.MINIFS($J:$J,$D:$D,$D11))/(_xlfn.MAXIFS($J:$J,$D:$D,$D11)-_xlfn.MINIFS($J:$J,$D:$D,$D11)) + 0.125*(K11-_xlfn.MINIFS($K:$K,$D:$D,$D11))/(_xlfn.MAXIFS($K:$K,$D:$D,$D11)-_xlfn.MINIFS($K:$K,$D:$D,$D11)), "") -> 0.61609778 | O11: 0.49592611 | P11: =1 + COUNTIFS($D$2:$D$2303, D11, $N$2:$N$2303, ">" & N11) -> 5 | Q11: 4 | R11: https://img.logo.dev/www.bsc.edu?token=pk_Zxmaeq2VQBuxgzPsrb7eBg&size=256 | S11: www.bsc.edu
A12: 101116 | B12: South University-Montgomery | C12: Montgomery | D12: AL | E12: www.southuniversity.edu/ | F12: 0.934 | G12: 1161 | H12: 18238 | I12: 18238 | J12: 59826 | K12: 28684 | L12: 29770 | M12: 35237 | N12: =IFERROR( 0.25*(_xlfn.MAXIFS($H:$H,$D:$D,$D12)-H12)/(_xlfn.MAXIFS($H:$H,$D:$D,$D12)-_xlfn.MINIFS($H:$H,$D:$D,$D12)) + 0.2*(_xlfn.MAXIFS($F:$F,$D:$D,$D12)-F12)/(_xlfn.MAXIFS($F:$F,$D:$D,$D12)-_xlfn.MINIFS($F:$F,$D:$D,$D12)) + 0.3*(G12-_xlfn.MINIFS($G:$G,$D:$D,$D12))/(_xlfn.MAXIFS($G:$G,$D:$D,$D12)-_xlfn.MINIFS($G:$G,$D:$D,$D12)) + 0.125*(J12-_xlfn.MINIFS($J:$J,$D:$D,$D12))/(_xlfn.MAXIFS($J:$J,$D:$D,$D12)-_xlfn.MINIFS($J:$J,$D:$D,$D12)) + 0.125*(K12-_xlfn.MINIFS($K:$K,$D:$D,$D12))/(_xlfn.MAXIFS($K:$K,$D:$D,$D12)-_xlfn.MINIFS($K:$K,$D:$D,$D12)), "") -> 0.4392596 | O12: 0.41018964 | P12: =1 + COUNTIFS($D$2:$D$2303, D12, $N$2:$N$2303, ">" & N12) -> 20 | Q12: 21 | R12: https://img.logo.dev/www.southuniversity.edu?token=pk_Zxmaeq2VQBuxgzPsrb7eBg&size=256 | S12: www.southuniversity.edu
A13: 101189 | B13: Faulkner University | C13: Montgomery | D13: AL | E13: www.faulkner.edu/ | F13: 0.6613 | G13: 1016 | H13: 23920 | I13: 23920 | J13: 46793 | K13: 36092 | L13: 37927 | M13: 41523 | N13: =IFERROR( 0.25*(_xlfn.MAXIFS($H:$H,$D:$D,$D13)-H13)/(_xlfn.MAXIFS($H:$H,$D:$D,$D13)-_xlfn.MINIFS($H:$H,$D:$D,$D13)) + 0.2*(_xlfn.MAXIFS($F:$F,$D:$D,$D13)-F13)/(_xlfn.MAXIFS($F:$F,$D:$D,$D13)-_xlfn.MINIFS($F:$F,$D:$D,$D13)) + 0.3*(G13-_xlfn.MINIFS($G:$G,$D:$D,$D13))/(_xlfn.MAXIFS($G:$G,$D:$D,$D13)-_xlfn.MINIFS($G:$G,$D:$D,$D13)) + 0.125*(J13-_xlfn.MINIFS($J:$J,$D:$D,$D13))/(_xlfn.MAXIFS($J:$J,$D:$D,$D13)-_xlfn.MINIFS($J:$J,$D:$D,$D13)) + 0.125*(K13-_xlfn.MINIFS($K:$K,$D:$D,$D13))/(_xlfn.MAXIFS($K:$K,$D:$D,$D13)-_xlfn.MINIFS($K:$K,$D:$D,$D13)), "") -> 0.35279005 | O13: 0.38691565 | P13: =1 + COUNTIFS($D$2:$D$2303, D13, $N$2:$N$2303, ">" & N13) -> 28 | Q13: 32 | R13: https://img.logo.dev/www.faulkner.edu?token=pk_Zxmaeq2VQBuxgzPsrb7eBg&size=256 | S13: www.faulkner.edu
A14: 101365 | B14: Herzing University-Birmingham | C14: Birmingham | D14: AL | E14: https://www.herzing.edu/ | F14: 0.9449 | G14: 1215 | H14: 13420 | I14: 13420 | J14: 48660 | K14: 33074 | L14: 32367 | M14: 34238 | N14: =IFERROR( 0.25*(_xlfn.MAXIFS($H:$H,$D:$D,$D14)-H14)/(_xlfn.MAXIFS($H:$H,$D:$D,$D14)-_xlfn.MINIFS($H:$H,$D:$D,$D14)) + 0.2*(_xlfn.MAXIFS($F:$F,$D:$D,$D14)-F14)/(_xlfn.MAXIFS($F:$F,$D:$D,$D14)-_xlfn.MINIFS($F:$F,$D:$D,$D14)) + 0.3*(G14-_xlfn.MINIFS($G:$G,$D:$D,$D14))/(_xlfn.MAXIFS($G:$G,$D:$D,$D14)-_xlfn.MINIFS($G:$G,$D:$D,$D14)) + 0.125*(J14-_xlfn.MINIFS($J:$J,$D:$D,$D14))/(_xlfn.MAXIFS($J:$J,$D:$D,$D14)-_xlfn.MINIFS($J:$J,$D:$D,$D14)) + 0.125*(K14-_xlfn.MINIFS($K:$K,$D:$D,$D14))/(_xlfn.MAXIFS($K:$K,$D:$D,$D14)-_xlfn.MINIFS($K:$K,$D:$D,$D14)), "") -> 0.50333532 | O14: 0.40576955 | P14: =1 + COUNTIFS($D$2:$D$2303, D14, $N$2:$N$2303, ">" & N14) -> 12 | Q14: 22 | R14: https://img.logo.dev/www.herzing.edu?token=pk_Zxmaeq2VQBuxgzPsrb7eBg&size=256 | S14: www.herzing.edu
... A2303: 243780 | B2303: Purdue University - Purdue Polytechnic Vincennes | C2303: Vincennes | D2303: IN | E2303: polytechnic.purdue.edu/vincennes | F2303: 0.934 | G2303: 1155 | H2303: 7400 | I2303: 7400 | J2303: 75853 | K2303: 57836 | L2303: 63112 | M2303: 68414 | N2303: =IFERROR( 0.25*(_xlfn.MAXIFS($H:$H,$D:$D,$D2303)-H2303)/(_xlfn.MAXIFS($H:$H,$D:$D,$D2303)-_xlfn.MINIFS($H:$H,$D:$D,$D2303)) + 0.2*(_xlfn.MAXIFS($F:$F,$D:$D,$D2303)-F2303)/(_xlfn.MAXIFS($F:$F,$D:$D,$D2303)-_xlfn.MINIFS($F:$F,$D:$D,$D2303)) + 0.3*(G2303-_xlfn.MINIFS($G:$G,$D:$D,$D2303))/(_xlfn.MAXIFS($G:$G,$D:$D,$D2303)-_xlfn.MINIFS($G:$G,$D:$D,$D2303)) + 0.125*(J2303-_xlfn.MINIFS($J:$J,$D:$D,$D2303))/(_xlfn.MAXIFS($J:$J,$D:$D,$D2303)-_xlfn.MINIFS($J:$J,$D:$D,$D2303)) + 0.125*(K2303-_xlfn.MINIFS($K:$K,$D:$D,$D2303))/(_xlfn.MAXIFS($K:$K,$D:$D,$D2303)-_xlfn.MINIFS($K:$K,$D:$D,$D2303)), "") -> 0.48989309 | O2303: 0.49167941 | P2303: =1 + COUNTIFS($D$2:$D$2303, D2303, $N$2:$N$2303, ">" & N2303) -> 9 | Q2303: 3 | R2303: https://img.logo.dev/polytechnic.purdue.edu?token=pk_Zxmaeq2VQBuxgzPsrb7eBg&size=256 | S2303: polytechnic.purdue.edu

Sheet Data
A2: School 1 | C2: School 1 $ | F2: School 1 Top Majors
F3: {=_xlfn.LET( _xlpm.result, _xlfn._xlws.FILTER(TopMajors[CIPTitle], TopMajors[UNITID] = A7), IFERROR(_xlpm.result, _xlfn.MAKEARRAY(5,1,_xlfn.LAMBDA(_xlpm.r,_xlpm.c,"NA"))) )} -> NA
A4: Ranking | C4: Year | D4: Median Earnings | F4: NA
A5: {=_xlfn.AGGREGATE(15, 6, SchoolRankings!$P$2:$P$2314 / ((SchoolRankings!$D$2:$D$2314 = Info!$G$3) * (SchoolRankings!$H$2:$H$2314 > 0) * (SchoolRankings!$H$2:$H$2314 <= Info!$C$3)), 1 )} -> #NUM! | C5: 2018 | D5: =_xlfn.XLOOKUP(A6,SchoolRankings!B:B,SchoolRankings!J:J) -> #N/A | F5: NA
A6: {=INDEX( SchoolRankings!$B$2:$B$2314, MATCH( 1, (SchoolRankings!$P$2:$P$2314 = Data!$A$5) * (SchoolRankings!$D$2:$D$2314 = Info!$G$3), 0 ) )} -> #N/A | C6: 2020 | D6: =_xlfn.XLOOKUP(A6,SchoolRankings!B:B,SchoolRankings!K:K) -> #N/A | F6: NA
A7: =_xlfn.XLOOKUP(A6,SchoolRankings!B:B,SchoolRankings!A:A) -> #N/A | C7: 2023 | D7: =_xlfn.XLOOKUP(A6,SchoolRankings!B:B,SchoolRankings!L:L) -> #N/A | F7: NA
A8: ="Rank # 1 " & A6 -> #N/A
A9: =_xlfn.XLOOKUP($A$6, SchoolRankings!$B$2:$B$2314, SchoolRankings!$R$2:$R$2314, "") -> #N/A
A11: Admissions
A12: =_xlfn.XLOOKUP(A6,SchoolRankings!B:B,SchoolRankings!F:F) -> #N/A
A13: =_xlfn.XLOOKUP(A6,SchoolRankings!B:B,SchoolRankings!H:H) -> #N/A
A15: SAT 1
A16: 1600
A17: =_xlfn.XLOOKUP(A6,SchoolRankings!B:B,SchoolRankings!G:G) -> #N/A
A18: =A16-A17 -> #N/A
A19: Avg SAT
A22: School 2 | C22: School 2 | F22: School 2 Top Majors
F23: {=_xlfn.LET( _xlpm.result, _xlfn._xlws.FILTER(TopMajors[CIPTitle], TopMajors[UNITID] = A27), IFERROR(_xlpm.result, _xlfn.MAKEARRAY(5,1,_xlfn.LAMBDA(_xlpm.r,_xlpm.c,"NA"))) )} -> NA
A24: Ranking | C24: Year | D24: Median Earnings | F24: NA
A25: {=_xlfn.AGGREGATE(15, 6, SchoolRankings!$P$2:$P$2314 / ((SchoolRankings!$D$2:$D$2314 = Info!$G$3) * (SchoolRankings!$H$2:$H$2314 > 0) * (SchoolRankings!$H$2:$H$2314 <= Info!$C$3)), 2 )} -> #NUM! | C25: 2018 | D25: =_xlfn.XLOOKUP(A26,SchoolRankings!B:B,SchoolRankings!J:J) -> #N/A | F25: NA
A26: {=INDEX( SchoolRankings!$B$2:$B$2314, MATCH( 1, (SchoolRankings!$P$2:$P$2314 = Data!A25) * (SchoolRankings!$D$2:$D$2314 = Info!$G$3), 0 ) )} -> #N/A | C26: 2020 | D26: =_xlfn.XLOOKUP(A26,SchoolRankings!B:B,SchoolRankings!K:K) -> #N/A | F26: NA
A27: =_xlfn.XLOOKUP(A26,SchoolRankings!B:B,SchoolRankings!A:A) -> #N/A | C27: 2023 | D27: =_xlfn.XLOOKUP(A26,SchoolRankings!B:B,SchoolRankings!L:L) -> #N/A | F27: NA
A28: ="Rank # 2 " & A26 -> #N/A
A29: =_xlfn.XLOOKUP($A$26, SchoolRankings!$B$2:$B$2314, SchoolRankings!$R$2:$R$2314, "") -> #N/A
A31: Admissions
A32: =_xlfn.XLOOKUP(A26,SchoolRankings!B:B,SchoolRankings!F:F) -> #N/A
A33: =_xlfn.XLOOKUP(A26,SchoolRankings!B:B,SchoolRankings!H:H) -> #N/A
A35: SAT 2
A36: 1600
A37: =_xlfn.XLOOKUP(A26,SchoolRankings!B:B,SchoolRankings!G:G) -> #N/A
A38: =A36-A37 -> #N/A
A39: ="SAT " & A37 -> #N/A
A42: School 3 | C42: School 3 | F42: School 3 Top Majors
F43: {=_xlfn.LET( _xlpm.result, _xlfn._xlws.FILTER(TopMajors[CIPTitle], TopMajors[UNITID] = A47), IFERROR(_xlpm.result, _xlfn.MAKEARRAY(5,1,_xlfn.LAMBDA(_xlpm.r,_xlpm.c,"NA"))) )} -> NA
A44: Ranking | C44: Year | D44: Median Earnings | F44: NA
A45: {=_xlfn.AGGREGATE(15, 6, SchoolRankings!$P$2:$P$2314 / ((SchoolRankings!$D$2:$D$2314 = Info!$G$3) * (SchoolRankings!$H$2:$H$2314 > 0) * (SchoolRankings!$H$2:$H$2314 <= Info!$C$3)), 3 )} -> #NUM! | C45: 2018 | D45: =_xlfn.XLOOKUP(A46,SchoolRankings!B:B,SchoolRankings!J:J) -> #N/A | F45: NA
A46: {=INDEX( SchoolRankings!$B$2:$B$2314, MATCH( 1, (SchoolRankings!$P$2:$P$2314 = Data!A45) * (SchoolRankings!$D$2:$D$2314 = Info!$G$3), 0 ) )} -> #N/A | C46: 2020 | D46: =_xlfn.XLOOKUP(A46,SchoolRankings!B:B,SchoolRankings!K:K) -> #N/A | F46: NA
A47: =_xlfn.XLOOKUP(A46,SchoolRankings!B:B,SchoolRankings!A:A) -> #N/A | C47: 2023 | D47: =_xlfn.XLOOKUP(A46,SchoolRankings!B:B,SchoolRankings!L:L) -> #N/A | F47: NA
A48: ="Rank # 2 " & A46 -> #N/A
A49: =_xlfn.XLOOKUP($A$46, SchoolRankings!$B$2:$B$2314, SchoolRankings!$R$2:$R$2314, "") -> #N/A
...

Sheet College Logo
A1: =IFERROR( _xlfn.IMAGE( _xlfn.XLOOKUP(Data!A6, SchoolRankings!B:B, SchoolRankings!R:R), "Logo", 1 ), _xlfn.IMAGE( "https://static.thenounproject.com/png/5034901-200.png", "Placeholder", 1 ) ) -> #VALUE! | F1: =IFERROR( _xlfn.IMAGE( _xlfn.XLOOKUP(Data!A26, SchoolRankings!B:B, SchoolRankings!R:R), "Logo", 1 ), _xlfn.IMAGE( "https://static.thenounproject.com/png/5034901-200.png", "Placeholder", 1 ) ) -> #VALUE! | K1: =IFERROR( _xlfn.IMAGE( _xlfn.XLOOKUP(Data!A46, SchoolRankings!B:B, SchoolRankings!R:R), "Logo", 1 ), _xlfn.IMAGE( "https://static.thenounproject.com/png/5034901-200.png", "Placeholder", 1 ) ) -> #VALUE! | P1: =IFERROR( _xlfn.IMAGE( _xlfn.XLOOKUP(Data!A66, SchoolRankings!B:B, SchoolRankings!R:R), 0, 1), _xlfn.IMAGE("https://static.thenounproject.com/png/5034901-200.png")=IFERROR( _xlfn.IMAGE( _xlfn.XLOOKUP(Data!A66, SchoolRankings!B:B, SchoolRankings!R:R), "Logo", 1 ), _xlfn.IMAGE( "https://static.thenounproject.com/png/5034901-200.png", "Placeholder", 1 ) ) ) -> FALSE | U1: =IFERROR( _xlfn.IMAGE( _xlfn.XLOOKUP(Data!A86, SchoolRankings!B:B, SchoolRankings!R:R), "Logo", 1 ), _xlfn.IMAGE( "https://static.thenounproject.com/png/5034901-200.png", "Placeholder", 1 ) ) -> #VALUE!

Sheet State
A1: Location | D1: In-State & Out-of-State
A2: AL | B2: Alabama | D2: In-State
A3: AK | B3: Alaska | D3: Out-of-State
A4: AZ | B4: Arizona
A5: AR | B5: Arkansas
A6: CA | B6: California
A7: CO | B7: Colorado
A8: CT | B8: Connecticut
A9: DE | B9: Delaware
A10: FL | B10: Florida
A11: GA | B11: Georgia
A12: HI | B12: Hawaii
A13: ID | B13: Idaho
A14: IL | B14: Illinois
A15: IN | B15: Indiana
... A51: WY | B51: Wyoming

Sheet MajorRank
A1: UNITID | B1: CIPCODE | C1: CTOTALT
A2: 100654 | B2: 1.0999 | C2: 12
A3: 100654 | B3: 1.1001 | C3: 10
A4: 100654 | B4: 1.9999 | C4: 2
A5: 100654 | B5: 3.0599 | C5: 0
A6: 100654 | B6: 4.0301 | C6: 8
A7: 100654 | B7: 10.0202 | C7: 32
A8: 100654 | B8: 11.0101 | C8: 25
A9: 100654 | B9: 13.1001 | C9: 0
A10: 100654 | B10: 13.1012 | C10: 11

Sheet CIPData
A1: CIPCode | B1: CIPTitle
A2: 1 | B2: Agriculture, General.
A3: 1.0101 | B3: Agricultural Business and Management, General.
A4: 1.0102 | B4: Agribusiness/Agricultural Business Operations.
A5: 1.0103 | B5: Agricultural Economics.
A6: 1.0104 | B6: Farm/Farm and Ranch Management.
A7: 1.0105 | B7: Agricultural/Farm Supplies Retailing and Wholesaling.
A8: 1.0106 | B8: Agricultural Business Technology/Technician.
A9: 1.0199 | B9: Agricultural Business and Management, Other.
A10: 1.0201 | B10: Agricultural Mechanization, General.

Sheet Top5Majors
A1: UNITID | B1: INSTNM | C1: CIPTitle
A2: 100654 | B2: Alabama A & M University | C2: Biology/Biological Sciences, General.
A3: 100654 | B3: Alabama A & M University | C3: Business Administration and Management, General.
A4: 100654 | B4: Alabama A & M University | C4: General Studies.
A5: 100654 | B5: Alabama A & M University | C5: Criminal Justice/Law Enforcement Administration.
A6: 100654 | B6: Alabama A & M University | C6: Mechanical Engineering.
A7: 100858 | B7: Auburn University | C7: Business Administration and Management, General.
A8: 100858 | B8: Auburn University | C8: Finance, General.
A9: 100858 | B9: Auburn University | C9: Marketing/Marketing Management, General.
A10: 100858 | B10: Auburn University | C10: Biomedical Sciences, General.
A11: 100858 | B11: Auburn University | C11: Registered Nursing/Registered Nurse.
A12: 100663 | B12: University of Alabama at Birmingham | C12: Registered Nursing/Registered Nurse.
A13: 100663 | B13: University of Alabama at Birmingham | C13: Psychology, General.
... A10017: 492962 | B10017: Indiana Institute of Technology-College of Professional Studies | C10017: Industrial Engineering.
A10018: 493363 | C10018: Bible/Biblical Studies.
A10019: 493512 | B10019: San Diego Global Knowledge University | C10019: Business Administration, Management and Operations, Other.
A10020: 493594 | B10020: Yeshiva of Ocean | C10020: Talmudic Studies.
A10021: 493600 | B10021: Congregation Talmidei Mesivta Tiferes Shmiel Aleksander | C10021: Talmudic Studies.
A10022: 493664 | B10022: Yeshivat Hechal Shemuel | C10022: Talmudic Studies.
A10023: 493673 | B10023: Professional University Dr. Carlos J. Borrero Rios | C10023: Registered Nursing/Registered Nurse.
A10024: 493707 | B10024: Yeshiva Gedolah of Woodlake Village | C10024: Talmudic Studies.
A10025: 493716 | B10025: Yeshiva Gedola Tiferes Yaakov Yitzchok | C10025: Talmudic Studies.
A10026: 493822 | B10026: College Unbound | C10026: Multi-/Interdisciplinary Studies, Other.
A10027: 493895 | B10027: SANS Technology Institute | C10027: Computer and Information Systems Security/Auditing/Information Assurance.
A10028: 493974 | B10028: College of Athens | C10028: Christian Studies.
A10029: 494162 | B10029: Arizona College of Nursing-Dallas | C10029: Registered Nursing/Registered Nurse.
A10030: 494278 | B10030: EDP University of Puerto Rico-Humacao | C10030: Nursing Science.
... A10067: 496399 | B10067: Agape College of Business and Science | C10067: Clinical/Medical Social Work.
A10068: 496405 | C10068: Philosophy.
A10069: 496405 | C10069: Psychology, General.
A10070: 496405 | C10070: Business/Commerce, General.
A10071: 496405 | C10071: Liberal Arts and Sciences/Liberal Studies.
A10072: 496627 | B10072: California Northstate University | C10072: Health Services/Allied Health/Health Sciences, General.
A10073: 496627 | B10073: California Northstate University | C10073: Health Services/Allied Health/Health Sciences, General.
A10074: 496627 | B10074: California Northstate University | C10074: HEALTH PROFESSIONS AND RELATED PROGRAMS.
A10075: 496636 | B10075: Antigua College International | C10075: Registered Nursing/Registered Nurse.
A10076: 496681 | B10076: Florida Academy of Nursing | C10076: Registered Nursing/Registered Nurse.
A10077: 496706 | B10077: Lakewood University | C10077: Non-Professional Legal Studies, Other.
A10078: 496706 | B10078: Lakewood University | C10078: Health/Health Care Administration/Management.
A10079: 496706 | B10079: Lakewood University | C10079: Business Administration and Management, General.
...
